<mujoco model="power_switch">
  <asset>
    <material name="MatPlasticDark"  rgba="0.08 0.08 0.09 1" specular="0.2" shininess="0.2"/>
    <material name="MatPlasticLight" rgba="0.85 0.85 0.86 1" specular="0.2" shininess="0.2"/>
    <material name="MatMetal"        rgba="0.45 0.45 0.48 1" specular="0.8" shininess="0.6"/>
    <material name="MatRed"          rgba="0.75 0.12 0.12 1" specular="0.3" shininess="0.2"/>
    <material name="MatGreen"        rgba="0.12 0.65 0.20 1" specular="0.3" shininess="0.2"/>
  </asset>

  <worldbody>
    <body>     <!-- do not remove this body -->
      <body name="object" pos="0 0 0">

        <!-- Mass scaled by 8× -->
        <inertial pos="0 0 0.04" mass="2.8"
                  diaginertia="0.0096 0.0096 0.012"/>
        <site name="origin" pos="0 0 0" size="0.01" rgba="0 0 0 0"/>

        <!-- ===================== Housing ===================== -->
        <geom name="housing_vis"
              type="box" pos="0 0 0.04" size="0.09 0.06 0.04"
              material="MatPlasticDark" group="1" contype="0" conaffinity="0"/>
        <!-- <geom name="housing_col"
              type="box" pos="0 0 0.04" size="0.09 0.06 0.04"
              rgba="0 0 0 0" group="0" friction="1 0.02 0.0005"/> -->

        <geom name="panel_vis"
              type="box" pos="0 0.063 0.044" size="0.08 0.004 0.06"
              material="MatPlasticLight" group="1" contype="0" conaffinity="0"/>

        <geom name="slot_vis"
              type="box" pos="-0.052 0.066 0.044" size="0.006 0.0024 0.04"
              material="MatPlasticDark" group="1" contype="0" conaffinity="0"/>

        <geom name="indicator_green_vis"
              type="cylinder" pos="0.052 0.066 0.048" size="0.0064 0.0024"
              material="MatGreen" group="1" contype="0" conaffinity="0"/>
        <geom name="indicator_red_vis"
              type="cylinder" pos="0.052 0.066 0.024" size="0.0064 0.0024"
              material="MatRed" group="1" contype="0" conaffinity="0"/>

        <!-- ===================== Lever ===================== -->
        <body name="lever" pos="-0.028 0.0674 0.044">
          <joint name="lever_hinge"
                 type="hinge"
                 pos="0 0 0"
                 axis="1 0 0"
                 limited="true"
                 range="-1 1"
                 damping="3.0"
                 frictionloss="0.08"
                 armature="0.0012"
                 ref="0"/>

          <inertial pos="0 0 0.02" mass="0.1"
                    diaginertia="0.00016 0.00016 0.00024"/>

          <geom name="lever_base_vis"
                type="cylinder" pos="0 0 0" size="0.013 0.005"
                material="MatMetal" group="1" contype="0" conaffinity="0"/>

          <geom name="lever_handle_vis"
                type="capsule" pos="0 0.024 0" size="0.006 0.024"
                quat="0.70710678 0.70710678 0 0"
                material="MatMetal" group="1" contype="0" conaffinity="0"/>

          <geom name="lever_knob_vis"
                type="cylinder" pos="0 0.052 0" size="0.011 0.012"
                quat="0.70710678 0.70710678 0 0"
                material="MatPlasticDark" group="1" contype="0" conaffinity="0"/>

          <geom name="lever_col"
                type="capsule" pos="0 0.024 0" size="0.0072 0.026"
                quat="0.70710678 0.70710678 0 0"
                rgba="0 0 0 0" group="0"
                friction="0.9 0.02 0.0005"/>

          <site name="lever_tip_site" pos="0 0.052 0" size="0.008" rgba="0 0 0 0"/>
        </body>

        <!-- Optional mount sites -->
        <site name="bottom_site" pos="0 0 0" size="0.01" rgba="0 0 0 0"/>
        <site name="top_site"    pos="0 0 0.11" size="0.01" rgba="0 0 0 0"/>

      </body>
    </body>
  </worldbody>
</mujoco>
